Workbook

Sheet KPI Review
D1: ZZEM | J1: 사주 | P1: Speaking
A2: sql과 맞는 Metric | B2: sql과 맞는 Metric | C2: 지표 | D2: W-2 | E2: W-1 | F2: 변화 | G2: M-1 | H2: M0 | I2: 변화 | J2: W-2 | K2: W-1 | L2: 변화 | M2: M-1 | N2: M0 | O2: 변화 | P2: W-2 | Q2: W-1 | R2: 변화 | S2: M-1 | T2: M0 | U2: 변화
A3: Paid_Cohort_Retention | B3: Paid_Cohort_Retention | C3: Paid Cohort Retention | D3: {=LET(val, IFERROR(INDEX('Weekly 쨈 raw'!$A:$AAQ, MATCH(TODAY() - WEEKDAY(TODAY(), 2) - 20, 'Weekly 쨈 raw'!$A:$A, 0), MATCH($A3, 'Weekly 쨈 raw'!$1:$1, 0)), ""), IF(val=0, "", val))} -> 0.46276596 | E3: {=LET(val, IFERROR(INDEX('Weekly 쨈 raw'!$A:$AAQ, MATCH(TODAY() - WEEKDAY(TODAY(), 2) - 13, 'Weekly 쨈 raw'!$A:$A, 0), MATCH($A3, 'Weekly 쨈 raw'!$1:$1, 0)), ""), IF(val=0, "", val))} -> 0.49603175 | F3: =LET(val, IF(OR(E3="", D3=""), "", IFERROR((E3 - D3) / D3, "")), IF(val=0, "", val)) -> 0.071884693 | G3: {=LET(val, IFERROR(INDEX('Monthly 쨈 M raw'!$A:$AAQ, MATCH(EOMONTH(TODAY(), -2) + 1, 'Monthly 쨈 M raw'!$A:$A, 0), MATCH($B3, 'Monthly 쨈 M raw'!$1:$1, 0)), 0), IF(val=0, "", val))} -> 0.60796545 | H3: {=LET(val, IFERROR(INDEX('Monthly 쨈 M raw'!$A:$AAQ, MATCH(EOMONTH(TODAY(), -1) + 1, 'Monthly 쨈 M raw'!$A:$A, 0), MATCH($B3, 'Monthly 쨈 M raw'!$1:$1, 0)), 0), IF(val=0, "", val))} -> 0.48663102 | I3: =LET(val, IF(OR(G3="", H3=""), "", IFERROR((H3 - G3) / G3, "")), IF(val=0, "", val)) -> -0.19957456 | J3: {=LET(val, IFERROR(INDEX('Weekly 사주 raw'!$A:$AAQ, MATCH(TODAY() - WEEKDAY(TODAY(), 2) - 20, 'Weekly 사주 raw'!$A:$A, 0), MATCH($A3, 'Weekly 사주 raw'!$1:$1, 0)), ""), IF(val=0, "", val))} -> 0.36363636 | K3: {=LET(val, IFERROR(INDEX('Weekly 사주 raw'!$A:$AAQ, MATCH(TODAY() - WEEKDAY(TODAY(), 2) - 13, 'Weekly 사주 raw'!$A:$A, 0), MATCH($A3, 'Weekly 사주 raw'!$1:$1, 0)), ""), IF(val=0, "", val))} -> 0.38970588 | L3: =LET(val, IF(OR(K3="", J3=""), "", IFERROR((K3 - J3) / J3, "")), IF(val=0, "", val)) -> 0.071691176 | M3: {=LET(val, IFERROR(INDEX('Monthly 사주 M raw'!$A:$AAQ, MATCH(EOMONTH(TODAY(), -2) + 1, 'Monthly 사주 M raw'!$A:$A, 0), MATCH($B3, 'Monthly 사주 M raw'!$1:$1, 0)), ""), IF(val=0, "", val))} -> 0.41691843 | N3: {=LET(val, IFERROR(INDEX('Monthly 사주 M raw'!$A:$AAQ, MATCH(EOMONTH(TODAY(), -1) + 1, 'Monthly 사주 M raw'!$A:$A, 0), MATCH($B3, 'Monthly 사주 M raw'!$1:$1, 0)), ""), IF(val=0, "", val))} -> 0.44333333 | O3: =LET(val, IF(OR(M3="", N3=""), "", IFERROR((N3 - M3) / M3, "")), IF(val=0, "", val)) -> 0.063357488 | P3: {=LET(val, IFERROR(INDEX('Weekly 스피킹 raw'!$A:$AAQ, MATCH(TODAY() - WEEKDAY(TODAY(), 2) - 20, 'Weekly 스피킹 raw'!$A:$A, 0), MATCH($A3, 'Weekly 스피킹 raw'!$1:$1, 0)), ""), IF(val=0, "", val))} -> 0.89189189 | Q3: {=LET(val, IFERROR(INDEX('Weekly 스피킹 raw'!$A:$AAQ, MATCH(TODAY() - WEEKDAY(TODAY(), 2) - 13, 'Weekly 스피킹 raw'!$A:$A, 0), MATCH($A3, 'Weekly 스피킹 raw'!$1:$1, 0)), ""), IF(val=0, "", val))} -> 0.9 | R3: =LET(val, IFERROR((Q3 - P3) / P3, ""), IF(val=0, "", val)) -> 0.0090909091 | S3: {=LET(val, IFERROR(INDEX('Monthly 스피킹 M raw'!$A:$AAQ, MATCH(EOMONTH(TODAY(), -2) + 1, 'Monthly 스피킹 M raw'!$A:$A, 0), MATCH($B3, 'Monthly 스피킹 M raw'!$1:$1, 0)), ""), IF(val=0, "", val))} -> 0.85365854 | T3: {=LET(val, IFERROR(INDEX('Monthly 스피킹 M raw'!$A:$AAQ, MATCH(EOMONTH(TODAY(), -1) + 1, 'Monthly 스피킹 M raw'!$A:$A, 0), MATCH($B3, 'Monthly 스피킹 M raw'!$1:$1, 0)), ""), IF(val=0, "", val))} -> 0.82914573 | U3: =LET(val, IF(OR(S3="", T3=""), "", IFERROR((T3 - S3) / S3, "")), IF(val=0, "", val)) -> -0.028715004
A4: W1_Any_Event_User | B4: M1_Any_Event_User | C4: ㄴ x0 Any Event User | D4: {=LET(val, IFERROR(INDEX('Weekly 쨈 raw'!$A:$AAQ, MATCH(TODAY() - WEEKDAY(TODAY(), 2) - 20, 'Weekly 쨈 raw'!$A:$A, 0), MATCH($A4, 'Weekly 쨈 raw'!$1:$1, 0)), ""), IF(val=0, "", val))} -> 87 | E4: {=LET(val, IFERROR(INDEX('Weekly 쨈 raw'!$A:$AAQ, MATCH(TODAY() - WEEKDAY(TODAY(), 2) - 13, 'Weekly 쨈 raw'!$A:$A, 0), MATCH($A4, 'Weekly 쨈 raw'!$1:$1, 0)), ""), IF(val=0, "", val))} -> 125 | F4: =LET(val, IF(OR(E4="", D4=""), "", IFERROR((E4 - D4) / D4, "")), IF(val=0, "", val)) -> 0.43678161 | G4: {=LET(val, IFERROR(INDEX('Monthly 쨈 M raw'!$A:$AAQ, MATCH(EOMONTH(TODAY(), -2) + 1, 'Monthly 쨈 M raw'!$A:$A, 0), MATCH($B4, 'Monthly 쨈 M raw'!$1:$1, 0)), 0), IF(val=0, "", val))} -> 1267 | H4: {=LET(val, IFERROR(INDEX('Monthly 쨈 M raw'!$A:$AAQ, MATCH(EOMONTH(TODAY(), -1) + 1, 'Monthly 쨈 M raw'!$A:$A, 0), MATCH($B4, 'Monthly 쨈 M raw'!$1:$1, 0)), 0), IF(val=0, "", val))} -> 637 | I4: =LET(val, IF(OR(G4="", H4=""), "", IFERROR((H4 - G4) / G4, "")), IF(val=0, "", val)) -> -0.49723757 | J4: {=LET(val, IFERROR(INDEX('Weekly 사주 raw'!$A:$AAQ, MATCH(TODAY() - WEEKDAY(TODAY(), 2) - 20, 'Weekly 사주 raw'!$A:$A, 0), MATCH($A4, 'Weekly 사주 raw'!$1:$1, 0)), ""), IF(val=0, "", val))} -> 88 | K4: {=LET(val, IFERROR(INDEX('Weekly 사주 raw'!$A:$AAQ, MATCH(TODAY() - WEEKDAY(TODAY(), 2) - 13, 'Weekly 사주 raw'!$A:$A, 0), MATCH($A4, 'Weekly 사주 raw'!$1:$1, 0)), ""), IF(val=0, "", val))} -> 53 | L4: =LET(val, IF(OR(K4="", J4=""), "", IFERROR((K4 - J4) / J4, "")), IF(val=0, "", val)) -> -0.39772727 | M4: {=LET(val, IFERROR(INDEX('Monthly 사주 M raw'!$A:$AAQ, MATCH(EOMONTH(TODAY(), -2) + 1, 'Monthly 사주 M raw'!$A:$A, 0), MATCH($B4, 'Monthly 사주 M raw'!$1:$1, 0)), ""), IF(val=0, "", val))} -> 138 | N4: {=LET(val, IFERROR(INDEX('Monthly 사주 M raw'!$A:$AAQ, MATCH(EOMONTH(TODAY(), -1) + 1, 'Monthly 사주 M raw'!$A:$A, 0), MATCH($B4, 'Monthly 사주 M raw'!$1:$1, 0)), ""), IF(val=0, "", val))} -> 532 | O4: =LET(val, IF(OR(M4="", N4=""), "", IFERROR((N4 - M4) / M4, "")), IF(val=0, "", val)) -> 2.8550725 | P4: {=LET(val, IFERROR(INDEX('Weekly 스피킹 raw'!$A:$AAQ, MATCH(TODAY() - WEEKDAY(TODAY(), 2) - 20, 'Weekly 스피킹 raw'!$A:$A, 0), MATCH($A4, 'Weekly 스피킹 raw'!$1:$1, 0)), ""), IF(val=0, "", val))} -> 33 | Q4: {=LET(val, IFERROR(INDEX('Weekly 스피킹 raw'!$A:$AAQ, MATCH(TODAY() - WEEKDAY(TODAY(), 2) - 13, 'Weekly 스피킹 raw'!$A:$A, 0), MATCH($A4, 'Weekly 스피킹 raw'!$1:$1, 0)), ""), IF(val=0, "", val))} -> 18 | R4: =LET(val, IFERROR((Q4 - P4) / P4, ""), IF(val=0, "", val)) -> -0.45454545 | S4: {=LET(val, IFERROR(INDEX('Monthly 스피킹 M raw'!$A:$AAQ, MATCH(EOMONTH(TODAY(), -2) + 1, 'Monthly 스피킹 M raw'!$A:$A, 0), MATCH($B4, 'Monthly 스피킹 M raw'!$1:$1, 0)), ""), IF(val=0, "", val))} -> 35 | T4: {=LET(val, IFERROR(INDEX('Monthly 스피킹 M raw'!$A:$AAQ, MATCH(EOMONTH(TODAY(), -1) + 1, 'Monthly 스피킹 M raw'!$A:$A, 0), MATCH($B4, 'Monthly 스피킹 M raw'!$1:$1, 0)), ""), IF(val=0, "", val))} -> 165 | U4: =LET(val, IF(OR(S4="", T4=""), "", IFERROR((T4 - S4) / S4, "")), IF(val=0, "", val)) -> 3.7142857
A5: W0_Purchase_Done_User | B5: M0_Purchase_Done_User | C5: ㄴ x-1 Purchase Done User | D5: {=LET(val, IFERROR(INDEX('Weekly 쨈 raw'!$A:$AAQ, MATCH(TODAY() - WEEKDAY(TODAY(), 2) - 20, 'Weekly 쨈 raw'!$A:$A, 0), MATCH($A5, 'Weekly 쨈 raw'!$1:$1, 0)), ""), IF(val=0, "", val))} -> 188 | E5: {=LET(val, IFERROR(INDEX('Weekly 쨈 raw'!$A:$AAQ, MATCH(TODAY() - WEEKDAY(TODAY(), 2) - 13, 'Weekly 쨈 raw'!$A:$A, 0), MATCH($A5, 'Weekly 쨈 raw'!$1:$1, 0)), ""), IF(val=0, "", val))} -> 252 | F5: =LET(val, IFERROR((E5 - D5) / D5, ""), IF(val=0, "", val)) -> 0.34042553 | G5: {=LET(val, IFERROR(INDEX('Monthly 쨈 M raw'!$A:$AAQ, MATCH(EOMONTH(TODAY(), -2) + 1, 'Monthly 쨈 M raw'!$A:$A, 0), MATCH($B5, 'Monthly 쨈 M raw'!$1:$1, 0)), 0), IF(val=0, "", val))} -> 2084 | H5: {=LET(val, IFERROR(INDEX('Monthly 쨈 M raw'!$A:$AAQ, MATCH(EOMONTH(TODAY(), -1) + 1, 'Monthly 쨈 M raw'!$A:$A, 0), MATCH($B5, 'Monthly 쨈 M raw'!$1:$1, 0)), 0), IF(val=0, "", val))} -> 1309 | I5: =LET(val, IF(OR(G5="", H5=""), "", IFERROR((H5 - G5) / G5, "")), IF(val=0, "", val)) -> -0.371881 | J5: {=LET(val, IFERROR(INDEX('Weekly 사주 raw'!$A:$AAQ, MATCH(TODAY() - WEEKDAY(TODAY(), 2) - 20, 'Weekly 사주 raw'!$A:$A, 0), MATCH($A5, 'Weekly 사주 raw'!$1:$1, 0)), ""), IF(val=0, "", val))} -> 242 | K5: {=LET(val, IFERROR(INDEX('Weekly 사주 raw'!$A:$AAQ, MATCH(TODAY() - WEEKDAY(TODAY(), 2) - 13, 'Weekly 사주 raw'!$A:$A, 0), MATCH($A5, 'Weekly 사주 raw'!$1:$1, 0)), ""), IF(val=0, "", val))} -> 136 | L5: =LET(val, IFERROR((K5 - J5) / J5, ""), IF(val=0, "", val)) -> -0.43801653 | M5: {=LET(val, IFERROR(INDEX('Monthly 사주 M raw'!$A:$AAQ, MATCH(EOMONTH(TODAY(), -2) + 1, 'Monthly 사주 M raw'!$A:$A, 0), MATCH($B5, 'Monthly 사주 M raw'!$1:$1, 0)), ""), IF(val=0, "", val))} -> 331 | N5: {=LET(val, IFERROR(INDEX('Monthly 사주 M raw'!$A:$AAQ, MATCH(EOMONTH(TODAY(), -1) + 1, 'Monthly 사주 M raw'!$A:$A, 0), MATCH($B5, 'Monthly 사주 M raw'!$1:$1, 0)), ""), IF(val=0, "", val))} -> 1200 | O5: =LET(val, IF(OR(M5="", N5=""), "", IFERROR((N5 - M5) / M5, "")), IF(val=0, "", val)) -> 2.6253776 | P5: {=LET(val, IFERROR(INDEX('Weekly 스피킹 raw'!$A:$AAQ, MATCH(TODAY() - WEEKDAY(TODAY(), 2) - 20, 'Weekly 스피킹 raw'!$A:$A, 0), MATCH($A5, 'Weekly 스피킹 raw'!$1:$1, 0)), ""), IF(val=0, "", val))} -> 37 | Q5: {=LET(val, IFERROR(INDEX('Weekly 스피킹 raw'!$A:$AAQ, MATCH(TODAY() - WEEKDAY(TODAY(), 2) - 13, 'Weekly 스피킹 raw'!$A:$A, 0), MATCH($A5, 'Weekly 스피킹 raw'!$1:$1, 0)), ""), IF(val=0, "", val))} -> 20 | R5: =LET(val, IFERROR((Q5 - P5) / P5, ""), IF(val=0, "", val)) -> -0.45945946 | S5: {=LET(val, IFERROR(INDEX('Monthly 스피킹 M raw'!$A:$AAQ, MATCH(EOMONTH(TODAY(), -2) + 1, 'Monthly 스피킹 M raw'!$A:$A, 0), MATCH($B5, 'Monthly 스피킹 M raw'!$1:$1, 0)), ""), IF(val=0, "", val))} -> 41 | T5: {=LET(val, IFERROR(INDEX('Monthly 스피킹 M raw'!$A:$AAQ, MATCH(EOMONTH(TODAY(), -1) + 1, 'Monthly 스피킹 M raw'!$A:$A, 0), MATCH($B5, 'Monthly 스피킹 M raw'!$1:$1, 0)), ""), IF(val=0, "", val))} -> 199 | U5: =LET(val, IF(OR(S5="", T5=""), "", IFERROR((T5 - S5) / S5, "")), IF(val=0, "", val)) -> 3.8536585
A7: CVR | B7: CVR | C7: CVR | D7: {=LET(val, IFERROR(INDEX('Weekly 쨈 raw'!$A:$AAQ, MATCH(TODAY() - WEEKDAY(TODAY(), 2) - 13, 'Weekly 쨈 raw'!$A:$A, 0), MATCH($A7, 'Weekly 쨈 raw'!$1:$1, 0)), ""), IF(val=0, "", val))} -> 0.1596474 | E7: {=LET(val, IFERROR(INDEX('Weekly 쨈 raw'!$A:$AAQ, MATCH(TODAY() - WEEKDAY(TODAY(), 2) - 6, 'Weekly 쨈 raw'!$A:$A, 0), MATCH($A7, 'Weekly 쨈 raw'!$1:$1, 0)), ""), IF(val=0, "", val))} -> 0.20490072 | F7: =LET(val, IFERROR((E7 - D7) / D7, ""), IF(val=0, "", val)) -> 0.28345787 | G7: {=LET(val, IFERROR(INDEX('Monthly 쨈 M raw'!$A:$AAQ, MATCH(EOMONTH(TODAY(), -2) + 1, 'Monthly 쨈 M raw'!$A:$A, 0), MATCH($B7, 'Monthly 쨈 M raw'!$1:$1, 0)), 0), IF(val=0, "", val))} -> 0.17133465 | H7: {=LET(val, IFERROR(INDEX('Monthly 쨈 M raw'!$A:$AAQ, MATCH(EOMONTH(TODAY(), -1) + 1, 'Monthly 쨈 M raw'!$A:$A, 0), MATCH($B7, 'Monthly 쨈 M raw'!$1:$1, 0)), ""), IF(val=0, "", val))} -> 0.16825397 | I7: =LET(val, IF(OR(G7="", H7=""), "", IFERROR((H7 - G7) / G7, "")), IF(val=0, "", val)) -> -0.017980485 | J7: {=LET(val, IFERROR(INDEX('Weekly 사주 raw'!$A:$AAQ, MATCH(TODAY() - WEEKDAY(TODAY(), 2) - 13, 'Weekly 사주 raw'!$A:$A, 0), MATCH($A7, 'Weekly 사주 raw'!$1:$1, 0)), ""), IF(val=0, "", val))} -> 0.13826607 | K7: {=LET(val, IFERROR(INDEX('Weekly 사주 raw'!$A:$AAQ, MATCH(TODAY() - WEEKDAY(TODAY(), 2) - 6, 'Weekly 사주 raw'!$A:$A, 0), MATCH($A7, 'Weekly 사주 raw'!$1:$1, 0)), ""), IF(val=0, "", val))} -> 0.16679657 | L7: =LET(val, IFERROR((K7 - J7) / J7, ""), IF(val=0, "", val)) -> 0.20634493 | M7: {=LET(val, IFERROR(INDEX('Monthly 사주 M raw'!$A:$AAQ, MATCH(EOMONTH(TODAY(), -2) + 1, 'Monthly 사주 M raw'!$A:$A, 0), MATCH($B7, 'Monthly 사주 M raw'!$1:$1, 0)), ""), IF(val=0, "", val))} -> 0.11255141 | N7: {=LET(val, IFERROR(INDEX('Monthly 사주 M raw'!$A:$AAQ, MATCH(EOMONTH(TODAY(), -1) + 1, 'Monthly 사주 M raw'!$A:$A, 0), MATCH($B7, 'Monthly 사주 M raw'!$1:$1, 0)), ""), IF(val=0, "", val))} -> 0.15896151 | O7: =LET(val, IF(OR(M7="", N7=""), "", IFERROR((N7 - M7) / M7, "")), IF(val=0, "", val)) -> 0.41234575 | P7: {=LET(val, IFERROR(INDEX('Weekly 스피킹 raw'!$A:$AAQ, MATCH(TODAY() - WEEKDAY(TODAY(), 2) - 13, 'Weekly 스피킹 raw'!$A:$A, 0), MATCH($A7, 'Weekly 스피킹 raw'!$1:$1, 0)), ""), IF(val=0, "", val))} -> 0.0029631143 | Q7: {=LET(val, IFERROR(INDEX('Weekly 스피킹 raw'!$A:$AAQ, MATCH(TODAY() - WEEKDAY(TODAY(), 2) - 6, 'Weekly 스피킹 raw'!$A:$A, 0), MATCH($A7, 'Weekly 스피킹 raw'!$1:$1, 0)), ""), IF(val=0, "", val))} -> 0.0034466366 | R7: =LET(val, IFERROR((Q7 - P7) / P7, ""), IF(val=0, "", val)) -> 0.16318041 | S7: {=LET(val, IFERROR(INDEX('Monthly 스피킹 M raw'!$A:$AAQ, MATCH(EOMONTH(TODAY(), -2) + 1, 'Monthly 스피킹 M raw'!$A:$A, 0), MATCH($B7, 'Monthly 스피킹 M raw'!$1:$1, 0)), ""), IF(val=0, "", val))} -> 0.0050385479 | T7: {=LET(val, IFERROR(INDEX('Monthly 스피킹 raw'!$A:$AAQ, MATCH(EOMONTH(TODAY(), -1) + 1, 'Monthly 스피킹 raw'!$A:$A, 0), MATCH($B7, 'Monthly 스피킹 raw'!$1:$1, 0)), ""), IF(val=0, "", val))} -> 0.0051045538 | U7: =LET(val, IF(OR(S7="", T7=""), "", IFERROR((T7 - S7) / S7, "")), IF(val=0, "", val)) -> 0.013100178
A8: Purchase_Done_User_CVR | B8: Purchase_Done_User_CVR | C8: ㄴ Purchase Done User | D8: {=LET(val, IFERROR(INDEX('Weekly 쨈 raw'!$A:$AAQ, MATCH(TODAY() - WEEKDAY(TODAY(), 2) - 13, 'Weekly 쨈 raw'!$A:$A, 0), MATCH($A8, 'Weekly 쨈 raw'!$1:$1, 0)), ""), IF(val=0, "", val))} -> 326 | E8: {=LET(val, IFERROR(INDEX('Weekly 쨈 raw'!$A:$AAQ, MATCH(TODAY() - WEEKDAY(TODAY(), 2) - 6, 'Weekly 쨈 raw'!$A:$A, 0), MATCH($A8, 'Weekly 쨈 raw'!$1:$1, 0)), ""), IF(val=0, "", val))} -> 485 | F8: =LET(val, IFERROR((E8 - D8) / D8, ""), IF(val=0, "", val)) -> 0.48773006 | G8: {=LET(val, IFERROR(INDEX('Monthly 쨈 M raw'!$A:$AAQ, MATCH(EOMONTH(TODAY(), -2) + 1, 'Monthly 쨈 M raw'!$A:$A, 0), MATCH($B8, 'Monthly 쨈 M raw'!$1:$1, 0)), ""), IF(val=0, "", val))} -> 1303 | H8: {=LET(val, IFERROR(INDEX('Monthly 쨈 M raw'!$A:$AAQ, MATCH(EOMONTH(TODAY(), -1) + 1, 'Monthly 쨈 M raw'!$A:$A, 0), MATCH($B8, 'Monthly 쨈 M raw'!$1:$1, 0)), ""), IF(val=0, "", val))} -> 1060 | I8: =LET(val, IF(OR(G8="", H8=""), "", IFERROR((H8 - G8) / G8, "")), IF(val=0, "", val)) -> -0.18649271 | J8: {=LET(val, IFERROR(INDEX('Weekly 사주 raw'!$A:$AAQ, MATCH(TODAY() - WEEKDAY(TODAY(), 2) - 13, 'Weekly 사주 raw'!$A:$A, 0), MATCH($A8, 'Weekly 사주 raw'!$1:$1, 0)), ""), IF(val=0, "", val))} -> 185 | K8: {=LET(val, IFERROR(INDEX('Weekly 사주 raw'!$A:$AAQ, MATCH(TODAY() - WEEKDAY(TODAY(), 2) - 6, 'Weekly 사주 raw'!$A:$A, 0), MATCH($A8, 'Weekly 사주 raw'!$1:$1, 0)), ""), IF(val=0, "", val))} -> 214 | L8: =LET(val, IFERROR((K8 - J8) / J8, ""), IF(val=0, "", val)) -> 0.15675676 | M8: {=LET(val, IFERROR(INDEX('Monthly 사주 M raw'!$A:$AAQ, MATCH(EOMONTH(TODAY(), -2) + 1, 'Monthly 사주 M raw'!$A:$A, 0), MATCH($B8, 'Monthly 사주 M raw'!$1:$1, 0)), ""), IF(val=0, "", val))} -> 903 | N8: {=LET(val, IFERROR(INDEX('Monthly 사주 M raw'!$A:$AAQ, MATCH(EOMONTH(TODAY(), -1) + 1, 'Monthly 사주 M raw'!$A:$A, 0), MATCH($B8, 'Monthly 사주 M raw'!$1:$1, 0)), ""), IF(val=0, "", val))} -> 698 | O8: =LET(val, IF(OR(M8="", N8=""), "", IFERROR((N8 - M8) / M8, "")), IF(val=0, "", val)) -> -0.22702104 | P8: {=LET(val, IFERROR(INDEX('Weekly 스피킹 raw'!$A:$AAQ, MATCH(TODAY() - WEEKDAY(TODAY(), 2) - 13, 'Weekly 스피킹 raw'!$A:$A, 0), MATCH($A8, 'Weekly 스피킹 raw'!$1:$1, 0)), ""), IF(val=0, "", val))} -> 29 | Q8: {=LET(val, IFERROR(INDEX('Weekly 스피킹 raw'!$A:$AAQ, MATCH(TODAY() - WEEKDAY(TODAY(), 2) - 6, 'Weekly 스피킹 raw'!$A:$A, 0), MATCH($A8, 'Weekly 스피킹 raw'!$1:$1, 0)), ""), IF(val=0, "", val))} -> 29 | R8: =LET(val, IFERROR((Q8 - P8) / P8, ""), IF(val=0, "", val)) | S8: {=LET(val, IFERROR(INDEX('Monthly 스피킹 M raw'!$A:$AAQ, MATCH(EOMONTH(TODAY(), -2) + 1, 'Monthly 스피킹 M raw'!$A:$A, 0), MATCH($B8, 'Monthly 스피킹 M raw'!$1:$1, 0)), ""), IF(val=0, "", val))} -> 166 | T8: {=LET(val, IFERROR(INDEX('Monthly 스피킹 raw'!$A:$AAQ, MATCH(EOMONTH(TODAY(), -1) + 1, 'Monthly 스피킹 raw'!$A:$A, 0), MATCH($B8, 'Monthly 스피킹 raw'!$1:$1, 0)), ""), IF(val=0, "", val))} -> 114 | U8: =LET(val, IF(OR(S8="", T8=""), "", IFERROR((T8 - S8) / S8, "")), IF(val=0, "", val)) -> -0.31325301
A9: Gen_Done_User | B9: Gen_Done_User | C9: ㄴ Gen Done User | D9: {=LET(val, IFERROR(INDEX('Weekly 쨈 raw'!$A:$AAQ, MATCH(TODAY() - WEEKDAY(TODAY(), 2) - 13, 'Weekly 쨈 raw'!$A:$A, 0), MATCH($A9, 'Weekly 쨈 raw'!$1:$1, 0)), ""), IF(val=0, "", val))} -> 2042 | E9: {=LET(val, IFERROR(INDEX('Weekly 쨈 raw'!$A:$AAQ, MATCH(TODAY() - WEEKDAY(TODAY(), 2) - 6, 'Weekly 쨈 raw'!$A:$A, 0), MATCH($A9, 'Weekly 쨈 raw'!$1:$1, 0)), ""), IF(val=0, "", val))} -> 2367 | F9: =LET(val, IFERROR((E9 - D9) / D9, ""), IF(val=0, "", val)) -> 0.15915769 | G9: {=LET(val, IFERROR(INDEX('Monthly 쨈 M raw'!$A:$AAQ, MATCH(EOMONTH(TODAY(), -2) + 1, 'Monthly 쨈 M raw'!$A:$A, 0), MATCH($B9, 'Monthly 쨈 M raw'!$1:$1, 0)), ""), IF(val=0, "", val))} -> 7605 | H9: {=LET(val, IFERROR(INDEX('Monthly 쨈 M raw'!$A:$AAQ, MATCH(EOMONTH(TODAY(), -1) + 1, 'Monthly 쨈 M raw'!$A:$A, 0), MATCH($B9, 'Monthly 쨈 M raw'!$1:$1, 0)), ""), IF(val=0, "", val))} -> 6300 | I9: =LET(val, IF(OR(G9="", H9=""), "", IFERROR((H9 - G9) / G9, "")), IF(val=0, "", val)) -> -0.17159763 | J9: {=LET(val, IFERROR(INDEX('Weekly 사주 raw'!$A:$AAQ, MATCH(TODAY() - WEEKDAY(TODAY(), 2) - 13, 'Weekly 사주 raw'!$A:$A, 0), MATCH($A9, 'Weekly 사주 raw'!$1:$1, 0)), ""), IF(val=0, "", val))} -> 1338 | K9: {=LET(val, IFERROR(INDEX('Weekly 사주 raw'!$A:$AAQ, MATCH(TODAY() - WEEKDAY(TODAY(), 2) - 6, 'Weekly 사주 raw'!$A:$A, 0), MATCH($A9, 'Weekly 사주 raw'!$1:$1, 0)), ""), IF(val=0, "", val))} -> 1283 | L9: =LET(val, IFERROR((K9 - J9) / J9, ""), IF(val=0, "", val)) -> -0.041106129 | M9: {=LET(val, IFERROR(INDEX('Monthly 사주 M raw'!$A:$AAQ, MATCH(EOMONTH(TODAY(), -2) + 1, 'Monthly 사주 M raw'!$A:$A, 0), MATCH($B9, 'Monthly 사주 M raw'!$1:$1, 0)), ""), IF(val=0, "", val))} -> 8023 | N9: {=LET(val, IFERROR(INDEX('Monthly 사주 M raw'!$A:$AAQ, MATCH(EOMONTH(TODAY(), -1) + 1, 'Monthly 사주 M raw'!$A:$A, 0), MATCH($B9, 'Monthly 사주 M raw'!$1:$1, 0)), ""), IF(val=0, "", val))} -> 4391 | O9: =LET(val, IF(OR(M9="", N9=""), "", IFERROR((N9 - M9) / M9, "")), IF(val=0, "", val)) -> -0.45269849 | P9: {=LET(val, IFERROR(INDEX('Weekly 스피킹 raw'!$A:$AAQ, MATCH(TODAY() - WEEKDAY(TODAY(), 2) - 13, 'Weekly 스피킹 raw'!$A:$A, 0), MATCH($A9, 'Weekly 스피킹 raw'!$1:$1, 0)), ""), IF(val=0, "", val))} -> 9787 | Q9: {=LET(val, IFERROR(INDEX('Weekly 스피킹 raw'!$A:$AAQ, MATCH(TODAY() - WEEKDAY(TODAY(), 2) - 6, 'Weekly 스피킹 raw'!$A:$A, 0), MATCH($A9, 'Weekly 스피킹 raw'!$1:$1, 0)), ""), IF(val=0, "", val))} -> 8414 | R9: =LET(val, IFERROR((Q9 - P9) / P9, ""), IF(val=0, "", val)) -> -0.14028814 | S9: {=LET(val, IFERROR(INDEX('Monthly 스피킹 M raw'!$A:$AAQ, MATCH(EOMONTH(TODAY(), -2) + 1, 'Monthly 스피킹 M raw'!$A:$A, 0), MATCH($B9, 'Monthly 스피킹 M raw'!$1:$1, 0)), ""), IF(val=0, "", val))} -> 32946 | T9: {=LET(val, IFERROR(INDEX('Monthly 스피킹 raw'!$A:$AAQ, MATCH(EOMONTH(TODAY(), -1) + 1, 'Monthly 스피킹 raw'!$A:$A, 0), MATCH($B9, 'Monthly 스피킹 raw'!$1:$1, 0)), ""), IF(val=0, "", val))} -> 22333 | U9: =LET(val, IF(OR(S9="", T9=""), "", IFERROR((T9 - S9) / S9, "")), IF(val=0, "", val)) -> -0.32213319
A10: Gen_Done_Count | B10: Gen_Done_Count | C10: ㄴ Gen Done Count | D10: {=LET(val, IFERROR(INDEX('Weekly 쨈 raw'!$A:$AAQ, MATCH(TODAY() - WEEKDAY(TODAY(), 2) - 13, 'Weekly 쨈 raw'!$A:$A, 0), MATCH($A10, 'Weekly 쨈 raw'!$1:$1, 0)), ""), IF(val=0, "", val))} -> 7739 | E10: {=LET(val, IFERROR(INDEX('Weekly 쨈 raw'!$A:$AAQ, MATCH(TODAY() - WEEKDAY(TODAY(), 2) - 6, 'Weekly 쨈 raw'!$A:$A, 0), MATCH($A10, 'Weekly 쨈 raw'!$1:$1, 0)), ""), IF(val=0, "", val))} -> 8951 | F10: =LET(val, IFERROR((E10 - D10) / D10, ""), IF(val=0, "", val)) -> 0.15660938 | G10: {=LET(val, IFERROR(INDEX('Monthly 쨈 M raw'!$A:$AAQ, MATCH(EOMONTH(TODAY(), -2) + 1, 'Monthly 쨈 M raw'!$A:$A, 0), MATCH($B10, 'Monthly 쨈 M raw'!$1:$1, 0)), ""), IF(val=0, "", val))} -> 29720 | H10: {=LET(val, IFERROR(INDEX('Monthly 쨈 M raw'!$A:$AAQ, MATCH(EOMONTH(TODAY(), -1) + 1, 'Monthly 쨈 M raw'!$A:$A, 0), MATCH($B10, 'Monthly 쨈 M raw'!$1:$1, 0)), ""), IF(val=0, "", val))} -> 26580 | I10: =LET(val, IF(OR(G10="", H10=""), "", IFERROR((H10 - G10) / G10, "")), IF(val=0, "", val)) -> -0.10565276 | J10: {=LET(val, IFERROR(INDEX('Weekly 사주 raw'!$A:$AAQ, MATCH(TODAY() - WEEKDAY(TODAY(), 2) - 13, 'Weekly 사주 raw'!$A:$A, 0), MATCH($A10, 'Weekly 사주 raw'!$1:$1, 0)), ""), IF(val=0, "", val))} -> 3348 | K10: {=LET(val, IFERROR(INDEX('Weekly 사주 raw'!$A:$AAQ, MATCH(TODAY() - WEEKDAY(TODAY(), 2) - 6, 'Weekly 사주 raw'!$A:$A, 0), MATCH($A10, 'Weekly 사주 raw'!$1:$1, 0)), ""), IF(val=0, "", val))} -> 3239 | L10: =LET(val, IFERROR((K10 - J10) / J10, ""), IF(val=0, "", val)) -> -0.03255675 | M10: {=LET(val, IFERROR(INDEX('Monthly 사주 M raw'!$A:$AAQ, MATCH(EOMONTH(TODAY(), -2) + 1, 'Monthly 사주 M raw'!$A:$A, 0), MATCH($B10, 'Monthly 사주 M raw'!$1:$1, 0)), ""), IF(val=0, "", val))} -> 25804 | N10: {=LET(val, IFERROR(INDEX('Monthly 사주 M raw'!$A:$AAQ, MATCH(EOMONTH(TODAY(), -1) + 1, 'Monthly 사주 M raw'!$A:$A, 0), MATCH($B10, 'Monthly 사주 M raw'!$1:$1, 0)), ""), IF(val=0, "", val))} -> 11965 | O10: =LET(val, IF(OR(M10="", N10=""), "", IFERROR((N10 - M10) / M10, "")), IF(val=0, "", val)) -> -0.5363122 | P10: {=LET(val, IFERROR(INDEX('Weekly 스피킹 raw'!$A:$AAQ, MATCH(TODAY() - WEEKDAY(TODAY(), 2) - 13, 'Weekly 스피킹 raw'!$A:$A, 0), MATCH($A10, 'Weekly 스피킹 raw'!$1:$1, 0)), ""), IF(val=0, "", val))} -> 88753 | Q10: {=LET(val, IFERROR(INDEX('Weekly 스피킹 raw'!$A:$AAQ, MATCH(TODAY() - WEEKDAY(TODAY(), 2) - 6, 'Weekly 스피킹 raw'!$A:$A, 0), MATCH($A10, 'Weekly 스피킹 raw'!$1:$1, 0)), ""), IF(val=0, "", val))} -> 67528 | R10: =LET(val, IFERROR((Q10 - P10) / P10, ""), IF(val=0, "", val)) -> -0.23914685 | S10: {=LET(val, IFERROR(INDEX('Monthly 스피킹 M raw'!$A:$AAQ, MATCH(EOMONTH(TODAY(), -2) + 1, 'Monthly 스피킹 M raw'!$A:$A, 0), MATCH($B10, 'Monthly 스피킹 M raw'!$1:$1, 0)), ""), IF(val=0, "", val))} -> 634217 | T10: {=LET(val, IFERROR(INDEX('Monthly 스피킹 raw'!$A:$AAQ, MATCH(EOMONTH(TODAY(), -1) + 1, 'Monthly 스피킹 raw'!$A:$A, 0), MATCH($B10, 'Monthly 스피킹 raw'!$1:$1, 0)), ""), IF(val=0, "", val))} -> 293658 | U10: =LET(val, IF(OR(S10="", T10=""), "", IFERROR((T10 - S10) / S10, "")), IF(val=0, "", val)) -> -0.53697551
A12: ARPPU | B12: ARPPU | C12: ARPPU | D12: {=LET(val, IFERROR(INDEX('Weekly 쨈 raw'!$A:$AAQ, MATCH(TODAY() - WEEKDAY(TODAY(), 2) - 13, 'Weekly 쨈 raw'!$A:$A, 0), MATCH($A12, 'Weekly 쨈 raw'!$1:$1, 0)), ""), IF(val=0, "", val))} -> 18170.552 | E12: {=LET(val, IFERROR(INDEX('Weekly 쨈 raw'!$A:$AAQ, MATCH(TODAY() - WEEKDAY(TODAY(), 2) - 6, 'Weekly 쨈 raw'!$A:$A, 0), MATCH($A12, 'Weekly 쨈 raw'!$1:$1, 0)), ""), IF(val=0, "", val))} -> 17841.237 | F12: =LET(val, IFERROR((E12 - D12) / D12, ""), IF(val=0, "", val)) -> -0.018123557 | G12: {=LET(val, IFERROR(INDEX('Monthly 쨈 M raw'!$A:$AAQ, MATCH(EOMONTH(TODAY(), -2) + 1, 'Monthly 쨈 M raw'!$A:$A, 0), MATCH($B12, 'Monthly 쨈 M raw'!$1:$1, 0)), 0), IF(val=0, "", val))} -> 8511.2817 | H12: {=LET(val, IFERROR(INDEX('Monthly 쨈 M raw'!$A:$AAQ, MATCH(EOMONTH(TODAY(), -1) + 1, 'Monthly 쨈 M raw'!$A:$A, 0), MATCH($B12, 'Monthly 쨈 M raw'!$1:$1, 0)), ""), IF(val=0, "", val))} -> 18036.132 | I12: =LET(val, IF(OR(G12="", H12=""), "", IFERROR((H12 - G12) / G12, "")), IF(val=0, "", val)) -> 1.1190853 | J12: {=LET(val, IFERROR(INDEX('Weekly 사주 raw'!$A:$AAQ, MATCH(TODAY() - WEEKDAY(TODAY(), 2) - 13, 'Weekly 사주 raw'!$A:$A, 0), MATCH($A12, 'Weekly 사주 raw'!$1:$1, 0)), ""), IF(val=0, "", val))} -> 24025.405 | K12: {=LET(val, IFERROR(INDEX('Weekly 사주 raw'!$A:$AAQ, MATCH(TODAY() - WEEKDAY(TODAY(), 2) - 6, 'Weekly 사주 raw'!$A:$A, 0), MATCH($A12, 'Weekly 사주 raw'!$1:$1, 0)), ""), IF(val=0, "", val))} -> 24415.421 | L12: =LET(val, IFERROR((K12 - J12) / J12, ""), IF(val=0, "", val)) -> 0.016233447 | M12: {=LET(val, IFERROR(INDEX('Monthly 사주 M raw'!$A:$AAQ, MATCH(EOMONTH(TODAY(), -2) + 1, 'Monthly 사주 M raw'!$A:$A, 0), MATCH($B12, 'Monthly 사주 M raw'!$1:$1, 0)), ""), IF(val=0, "", val))} -> 23157.918 | N12: {=LET(val, IFERROR(INDEX('Monthly 사주 M raw'!$A:$AAQ, MATCH(EOMONTH(TODAY(), -1) + 1, 'Monthly 사주 M raw'!$A:$A, 0), MATCH($B12, 'Monthly 사주 M raw'!$1:$1, 0)), ""), IF(val=0, "", val))} -> 24889.398 | O12: =LET(val, IF(OR(M12="", N12=""), "", IFERROR((N12 - M12) / M12, "")), IF(val=0, "", val)) -> 0.074768389 | P12: {=LET(val, IFERROR(INDEX('Weekly 스피킹 raw'!$A:$AAQ, MATCH(TODAY() - WEEKDAY(TODAY(), 2) - 13, 'Weekly 스피킹 raw'!$A:$A, 0), MATCH($A12, 'Weekly 스피킹 raw'!$1:$1, 0)), ""), IF(val=0, "", val))} -> 59034.483 | Q12: {=LET(val, IFERROR(INDEX('Weekly 스피킹 raw'!$A:$AAQ, MATCH(TODAY() - WEEKDAY(TODAY(), 2) - 6, 'Weekly 스피킹 raw'!$A:$A, 0), MATCH($A12, 'Weekly 스피킹 raw'!$1:$1, 0)), ""), IF(val=0, "", val))} -> 76275.862 | R12: =LET(val, IFERROR((Q12 - P12) / P12, ""), IF(val=0, "", val)) -> 0.29205607 | S12: {=LET(val, IFERROR(INDEX('Monthly 스피킹 M raw'!$A:$AAQ, MATCH(EOMONTH(TODAY(), -2) + 1, 'Monthly 스피킹 M raw'!$A:$A, 0), MATCH($B12, 'Monthly 스피킹 M raw'!$1:$1, 0)), ""), IF(val=0, "", val))} -> 83102.41 | T12: {=LET(val, IFERROR(INDEX('Monthly 스피킹 raw'!$A:$AAQ, MATCH(EOMONTH(TODAY(), -1) + 1, 'Monthly 스피킹 raw'!$A:$A, 0), MATCH($B12, 'Monthly 스피킹 raw'!$1:$1, 0)), ""), IF(val=0, "", val))} -> 72833.333 | U12: =LET(val, IF(OR(S12="", T12=""), "", IFERROR((T12 - S12) / S12, "")), IF(val=0, "", val)) -> -0.12357134
A13: Revenue | B13: Revenue | C13: ㄴ Revenue | D13: {=LET(val, IFERROR(INDEX('Weekly 쨈 raw'!$A:$AAQ, MATCH(TODAY() - WEEKDAY(TODAY(), 2) - 13, 'Weekly 쨈 raw'!$A:$A, 0), MATCH($A13, 'Weekly 쨈 raw'!$1:$1, 0)), ""), IF(val=0, "", val))} -> 5923600 | E13: {=LET(val, IFERROR(INDEX('Weekly 쨈 raw'!$A:$AAQ, MATCH(TODAY() - WEEKDAY(TODAY(), 2) - 6, 'Weekly 쨈 raw'!$A:$A, 0), MATCH($A13, 'Weekly 쨈 raw'!$1:$1, 0)), ""), IF(val=0, "", val))} -> 8653000 | F13: =LET(val, IFERROR((E13 - D13) / D13, ""), IF(val=0, "", val)) -> 0.4607671 | G13: {=LET(val, IFERROR(INDEX('Monthly 쨈 M raw'!$A:$AAQ, MATCH(EOMONTH(TODAY(), -2) + 1, 'Monthly 쨈 M raw'!$A:$A, 0), MATCH($B13, 'Monthly 쨈 M raw'!$1:$1, 0)), 0), IF(val=0, "", val))} -> 11090200 | H13: {=LET(val, IFERROR(INDEX('Monthly 쨈 M raw'!$A:$AAQ, MATCH(EOMONTH(TODAY(), -1) + 1, 'Monthly 쨈 M raw'!$A:$A, 0), MATCH($B13, 'Monthly 쨈 M raw'!$1:$1, 0)), ""), IF(val=0, "", val))} -> 19118300 | I13: =LET(val, IF(OR(G13="", H13=""), "", IFERROR((H13 - G13) / G13, "")), IF(val=0, "", val)) -> 0.72389136 | J13: {=LET(val, IFERROR(INDEX('Weekly 사주 raw'!$A:$AAQ, MATCH(TODAY() - WEEKDAY(TODAY(), 2) - 13, 'Weekly 사주 raw'!$A:$A, 0), MATCH($A13, 'Weekly 사주 raw'!$1:$1, 0)), ""), IF(val=0, "", val))} -> 4444700 | K13: {=LET(val, IFERROR(INDEX('Weekly 사주 raw'!$A:$AAQ, MATCH(TODAY() - WEEKDAY(TODAY(), 2) - 6, 'Weekly 사주 raw'!$A:$A, 0), MATCH($A13, 'Weekly 사주 raw'!$1:$1, 0)), ""), IF(val=0, "", val))} -> 5224900 | L13: =LET(val, IFERROR((K13 - J13) / J13, ""), IF(val=0, "", val)) -> 0.17553491 | M13: {=LET(val, IFERROR(INDEX('Monthly 사주 M raw'!$A:$AAQ, MATCH(EOMONTH(TODAY(), -2) + 1, 'Monthly 사주 M raw'!$A:$A, 0), MATCH($B13, 'Monthly 사주 M raw'!$1:$1, 0)), ""), IF(val=0, "", val))} -> 20911600 | N13: {=LET(val, IFERROR(INDEX('Monthly 사주 M raw'!$A:$AAQ, MATCH(EOMONTH(TODAY(), -1) + 1, 'Monthly 사주 M raw'!$A:$A, 0), MATCH($B13, 'Monthly 사주 M raw'!$1:$1, 0)), ""), IF(val=0, "", val))} -> 17372800 | O13: =LET(val, IF(OR(M13="", N13=""), "", IFERROR((N13 - M13) / M13, "")), IF(val=0, "", val)) -> -0.16922665 | P13: {=LET(val, IFERROR(INDEX('Weekly 스피킹 raw'!$A:$AAQ, MATCH(TODAY() - WEEKDAY(TODAY(), 2) - 13, 'Weekly 스피킹 raw'!$A:$A, 0), MATCH($A13, 'Weekly 스피킹 raw'!$1:$1, 0)), ""), IF(val=0, "", val))} -> 1712000 | Q13: {=LET(val, IFERROR(INDEX('Weekly 스피킹 raw'!$A:$AAQ, MATCH(TODAY() - WEEKDAY(TODAY(), 2) - 6, 'Weekly 스피킹 raw'!$A:$A, 0), MATCH($A13, 'Weekly 스피킹 raw'!$1:$1, 0)), ""), IF(val=0, "", val))} -> 2212000 | R13: =LET(val, IFERROR((Q13 - P13) / P13, ""), IF(val=0, "", val)) -> 0.29205607 | S13: {=LET(val, IFERROR(INDEX('Monthly 스피킹 M raw'!$A:$AAQ, MATCH(EOMONTH(TODAY(), -2) + 1, 'Monthly 스피킹 M raw'!$A:$A, 0), MATCH($B13, 'Monthly 스피킹 M raw'!$1:$1, 0)), ""), IF(val=0, "", val))} -> 13795000 | T13: {=LET(val, IFERROR(INDEX('Monthly 스피킹 raw'!$A:$AAQ, MATCH(EOMONTH(TODAY(), -1) + 1, 'Monthly 스피킹 raw'!$A:$A, 0), MATCH($B13, 'Monthly 스피킹 raw'!$1:$1, 0)), ""), IF(val=0, "", val))} -> 8303000 | U13: =LET(val, IF(OR(S13="", T13=""), "", IFERROR((T13 - S13) / S13, "")), IF(val=0, "", val)) -> -0.39811526
A14: Purchase_Done_User_ARPPU | B14: Purchase_Done_User_ARPPU | C14: ㄴ Purchase Done User | D14: {=LET(val, IFERROR(INDEX('Weekly 쨈 raw'!$A:$AAQ, MATCH(TODAY() - WEEKDAY(TODAY(), 2) - 13, 'Weekly 쨈 raw'!$A:$A, 0), MATCH($A14, 'Weekly 쨈 raw'!$1:$1, 0)), ""), IF(val=0, "", val))} -> 326 | E14: {=LET(val, IFERROR(INDEX('Weekly 쨈 raw'!$A:$AAQ, MATCH(TODAY() - WEEKDAY(TODAY(), 2) - 6, 'Weekly 쨈 raw'!$A:$A, 0), MATCH($A14, 'Weekly 쨈 raw'!$1:$1, 0)), ""), IF(val=0, "", val))} -> 485 | F14: =LET(val, IFERROR((E14 - D14) / D14, ""), IF(val=0, "", val)) -> 0.48773006 | G14: {=LET(val, IFERROR(INDEX('Monthly 쨈 M raw'!$A:$AAQ, MATCH(EOMONTH(TODAY(), -2) + 1, 'Monthly 쨈 M raw'!$A:$A, 0), MATCH($B14, 'Monthly 쨈 M raw'!$1:$1, 0)), 0), IF(val=0, "", val))} -> 1303 | H14: {=LET(val, IFERROR(INDEX('Monthly 쨈 M raw'!$A:$AAQ, MATCH(EOMONTH(TODAY(), -1) + 1, 'Monthly 쨈 M raw'!$A:$A, 0), MATCH($B14, 'Monthly 쨈 M raw'!$1:$1, 0)), ""), IF(val=0, "", val))} -> 1060 | I14: =LET(val, IF(OR(G14="", H14=""), "", IFERROR((H14 - G14) / G14, "")), IF(val=0, "", val)) -> -0.18649271 | J14: {=LET(val, IFERROR(INDEX('Weekly 사주 raw'!$A:$AAQ, MATCH(TODAY() - WEEKDAY(TODAY(), 2) - 13, 'Weekly 사주 raw'!$A:$A, 0), MATCH($A14, 'Weekly 사주 raw'!$1:$1, 0)), ""), IF(val=0, "", val))} -> 185 | K14: {=LET(val, IFERROR(INDEX('Weekly 사주 raw'!$A:$AAQ, MATCH(TODAY() - WEEKDAY(TODAY(), 2) - 6, 'Weekly 사주 raw'!$A:$A, 0), MATCH($A14, 'Weekly 사주 raw'!$1:$1, 0)), ""), IF(val=0, "", val))} -> 214 | L14: =LET(val, IFERROR((K14 - J14) / J14, ""), IF(val=0, "", val)) -> 0.15675676 | M14: {=LET(val, IFERROR(INDEX('Monthly 사주 M raw'!$A:$AAQ, MATCH(EOMONTH(TODAY(), -2) + 1, 'Monthly 사주 M raw'!$A:$A, 0), MATCH($B14, 'Monthly 사주 M raw'!$1:$1, 0)), ""), IF(val=0, "", val))} -> 903 | N14: {=LET(val, IFERROR(INDEX('Monthly 사주 M raw'!$A:$AAQ, MATCH(EOMONTH(TODAY(), -1) + 1, 'Monthly 사주 M raw'!$A:$A, 0), MATCH($B14, 'Monthly 사주 M raw'!$1:$1, 0)), ""), IF(val=0, "", val))} -> 698 | O14: =LET(val, IF(OR(M14="", N14=""), "", IFERROR((N14 - M14) / M14, "")), IF(val=0, "", val)) -> -0.22702104 | P14: {=LET(val, IFERROR(INDEX('Weekly 스피킹 raw'!$A:$AAQ, MATCH(TODAY() - WEEKDAY(TODAY(), 2) - 13, 'Weekly 스피킹 raw'!$A:$A, 0), MATCH($A14, 'Weekly 스피킹 raw'!$1:$1, 0)), ""), IF(val=0, "", val))} -> 29 | Q14: {=LET(val, IFERROR(INDEX('Weekly 스피킹 raw'!$A:$AAQ, MATCH(TODAY() - WEEKDAY(TODAY(), 2) - 6, 'Weekly 스피킹 raw'!$A:$A, 0), MATCH($A14, 'Weekly 스피킹 raw'!$1:$1, 0)), ""), IF(val=0, "", val))} -> 29 | R14: =LET(val, IFERROR((Q14 - P14) / P14, ""), IF(val=0, "", val)) | S14: {=LET(val, IFERROR(INDEX('Monthly 스피킹 M raw'!$A:$AAQ, MATCH(EOMONTH(TODAY(), -2) + 1, 'Monthly 스피킹 M raw'!$A:$A, 0), MATCH($B14, 'Monthly 스피킹 M raw'!$1:$1, 0)), ""), IF(val=0, "", val))} -> 166 | T14: {=LET(val, IFERROR(INDEX('Monthly 스피킹 raw'!$A:$AAQ, MATCH(EOMONTH(TODAY(), -1) + 1, 'Monthly 스피킹 raw'!$A:$A, 0), MATCH($B14, 'Monthly 스피킹 raw'!$1:$1, 0)), ""), IF(val=0, "", val))} -> 114 | U14: =LET(val, IF(OR(S14="", T14=""), "", IFERROR((T14 - S14) / S14, "")), IF(val=0, "", val)) -> -0.31325301
A15: Purchase_Done_Count | B15: Purchase_Done_Count | C15: ㄴ Purchase Done Count | D15: {=LET(val, IFERROR(INDEX('Weekly 쨈 raw'!$A:$AAQ, MATCH(TODAY() - WEEKDAY(TODAY(), 2) - 13, 'Weekly 쨈 raw'!$A:$A, 0), MATCH($A15, 'Weekly 쨈 raw'!$1:$1, 0)), ""), IF(val=0, "", val))} -> 401 | E15: {=LET(val, IFERROR(INDEX('Weekly 쨈 raw'!$A:$AAQ, MATCH(TODAY() - WEEKDAY(TODAY(), 2) - 6, 'Weekly 쨈 raw'!$A:$A, 0), MATCH($A15, 'Weekly 쨈 raw'!$1:$1, 0)), ""), IF(val=0, "", val))} -> 621 | F15: =LET(val, IFERROR((E15 - D15) / D15, ""), IF(val=0, "", val)) -> 0.54862843 | G15: {=LET(val, IFERROR(INDEX('Monthly 쨈 M raw'!$A:$AAQ, MATCH(EOMONTH(TODAY(), -2) + 1, 'Monthly 쨈 M raw'!$A:$A, 0), MATCH($B15, 'Monthly 쨈 M raw'!$1:$1, 0)), 0), IF(val=0, "", val))} -> 1700 | H15: {=LET(val, IFERROR(INDEX('Monthly 쨈 M raw'!$A:$AAQ, MATCH(EOMONTH(TODAY(), -1) + 1, 'Monthly 쨈 M raw'!$A:$A, 0), MATCH($B15, 'Monthly 쨈 M raw'!$1:$1, 0)), ""), IF(val=0, "", val))} -> 1460 | I15: =LET(val, IF(OR(G15="", H15=""), "", IFERROR((H15 - G15) / G15, "")), IF(val=0, "", val)) -> -0.14117647 | J15: {=LET(val, IFERROR(INDEX('Weekly 사주 raw'!$A:$AAQ, MATCH(TODAY() - WEEKDAY(TODAY(), 2) - 13, 'Weekly 사주 raw'!$A:$A, 0), MATCH($A15, 'Weekly 사주 raw'!$1:$1, 0)), ""), IF(val=0, "", val))} -> 227 | K15: {=LET(val, IFERROR(INDEX('Weekly 사주 raw'!$A:$AAQ, MATCH(TODAY() - WEEKDAY(TODAY(), 2) - 6, 'Weekly 사주 raw'!$A:$A, 0), MATCH($A15, 'Weekly 사주 raw'!$1:$1, 0)), ""), IF(val=0, "", val))} -> 265 | L15: =LET(val, IFERROR((K15 - J15) / J15, ""), IF(val=0, "", val)) -> 0.16740088 | M15: {=LET(val, IFERROR(INDEX('Monthly 사주 M raw'!$A:$AAQ, MATCH(EOMONTH(TODAY(), -2) + 1, 'Monthly 사주 M raw'!$A:$A, 0), MATCH($B15, 'Monthly 사주 M raw'!$1:$1, 0)), ""), IF(val=0, "", val))} -> 1242 | N15: {=LET(val, IFERROR(INDEX('Monthly 사주 M raw'!$A:$AAQ, MATCH(EOMONTH(TODAY(), -1) + 1, 'Monthly 사주 M raw'!$A:$A, 0), MATCH($B15, 'Monthly 사주 M raw'!$1:$1, 0)), ""), IF(val=0, "", val))} -> 1028 | O15: =LET(val, IF(OR(M15="", N15=""), "", IFERROR((N15 - M15) / M15, "")), IF(val=0, "", val)) -> -0.17230274 | P15: {=LET(val, IFERROR(INDEX('Weekly 스피킹 raw'!$A:$AAQ, MATCH(TODAY() - WEEKDAY(TODAY(), 2) - 13, 'Weekly 스피킹 raw'!$A:$A, 0), MATCH($A15, 'Weekly 스피킹 raw'!$1:$1, 0)), ""), IF(val=0, "", val))} -> 29 | Q15: {=LET(val, IFERROR(INDEX('Weekly 스피킹 raw'!$A:$AAQ, MATCH(TODAY() - WEEKDAY(TODAY(), 2) - 6, 'Weekly 스피킹 raw'!$A:$A, 0), MATCH($A15, 'Weekly 스피킹 raw'!$1:$1, 0)), ""), IF(val=0, "", val))} -> 29 | R15: =LET(val, IFERROR((Q15 - P15) / P15, ""), IF(val=0, "", val)) | S15: {=LET(val, IFERROR(INDEX('Monthly 스피킹 M raw'!$A:$AAQ, MATCH(EOMONTH(TODAY(), -2) + 1, 'Monthly 스피킹 M raw'!$A:$A, 0), MATCH($B15, 'Monthly 스피킹 M raw'!$1:$1, 0)), ""), IF(val=0, "", val))} -> 167 | T15: {=LET(val, IFERROR(INDEX('Monthly 스피킹 raw'!$A:$AAQ, MATCH(EOMONTH(TODAY(), -1) + 1, 'Monthly 스피킹 raw'!$A:$A, 0), MATCH($B15, 'Monthly 스피킹 raw'!$1:$1, 0)), ""), IF(val=0, "", val))} -> 115 | U15: =LET(val, IF(OR(S15="", T15=""), "", IFERROR((T15 - S15) / S15, "")), IF(val=0, "", val)) -> -0.31137725
A17: Margin_Rate | B17: Margin_Rate | C17: 마진율 | D17: {=LET(val, IFERROR(INDEX('Weekly 쨈 raw'!$A:$AAQ, MATCH(TODAY() - WEEKDAY(TODAY(), 2) - 13, 'Weekly 쨈 raw'!$A:$A, 0), MATCH($A17, 'Weekly 쨈 raw'!$1:$1, 0)), ""), IF(val=0, "", val))} -> 0.31341969 | E17: {=LET(val, IFERROR(INDEX('Weekly 쨈 raw'!$A:$AAQ, MATCH(TODAY() - WEEKDAY(TODAY(), 2) - 6, 'Weekly 쨈 raw'!$A:$A, 0), MATCH($A17, 'Weekly 쨈 raw'!$1:$1, 0)), ""), IF(val=0, "", val))} -> 0.3147599 | F17: =LET(val, IFERROR((E17 - D17) / ABS(D17), ""), IF(val=0, "", val)) -> 0.0042760689 | G17: {=LET(val, IFERROR(INDEX('Monthly 쨈 M raw'!$A:$AAQ, MATCH(EOMONTH(TODAY(), -2) + 1, 'Monthly 쨈 M raw'!$A:$A, 0), MATCH($B17, 'Monthly 쨈 M raw'!$1:$1, 0)), 0), IF(val=0, "", val))} -> 0.11811167 | H17: {=LET(val, IFERROR(INDEX('Monthly 쨈 M raw'!$A:$AAQ, MATCH(EOMONTH(TODAY(), -1) + 1, 'Monthly 쨈 M raw'!$A:$A, 0), MATCH($B17, 'Monthly 쨈 M raw'!$1:$1, 0)), ""), IF(val=0, "", val))} -> 0.2965746 | I17: =LET(val, IF(OR(G17="", H17=""), "", IFERROR((H17 - G17) / ABS(G17), "")), IF(val=0, "", val)) -> 1.5109678 | J17: {=LET(val, IFERROR(INDEX('Weekly 사주 raw'!$A:$AAQ, MATCH(TODAY() - WEEKDAY(TODAY(), 2) - 13, 'Weekly 사주 raw'!$A:$A, 0), MATCH($A17, 'Weekly 사주 raw'!$1:$1, 0)), ""), IF(val=0, "", val))} -> 0.73759789 | K17: {=LET(val, IFERROR(INDEX('Weekly 사주 raw'!$A:$AAQ, MATCH(TODAY() - WEEKDAY(TODAY(), 2) - 6, 'Weekly 사주 raw'!$A:$A, 0), MATCH($A17, 'Weekly 사주 raw'!$1:$1, 0)), ""), IF(val=0, "", val))} -> 0.72691942 | L17: =LET(val, IF(OR(K17="", J17=""), "", IFERROR((K17 - J17) / ABS(J17), "")), IF(val=0, "", val)) -> -0.014477359 | M17: {=LET(val, IFERROR(INDEX('Monthly 사주 M raw'!$A:$AAQ, MATCH(EOMONTH(TODAY(), -2) + 1, 'Monthly 사주 M raw'!$A:$A, 0), MATCH($B17, 'Monthly 사주 M raw'!$1:$1, 0)), ""), IF(val=0, "", val))} -> 0.75190571 | N17: {=LET(val, IFERROR(INDEX('Monthly 사주 M raw'!$A:$AAQ, MATCH(EOMONTH(TODAY(), -1) + 1, 'Monthly 사주 M raw'!$A:$A, 0), MATCH($B17, 'Monthly 사주 M raw'!$1:$1, 0)), ""), IF(val=0, "", val))} -> 0.72349896 | O17: =LET(val, IF(OR(M17="", N17=""), "", IFERROR((N17 - M17) / ABS(M17), "")), IF(val=0, "", val)) -> -0.037779674 | P17: {=LET(val, IFERROR(INDEX('Weekly 스피킹'!$A:$AAQ, MATCH($A17, 'Weekly 스피킹'!$A:$A, 0), MATCH(TODAY() - WEEKDAY(TODAY(), 2) - 13, 'Weekly 스피킹'!$2:$2, 0)), ""), IF(val=0, "", val))} -> 0.31683995 | Q17: {=LET(val, IFERROR(INDEX('Weekly 스피킹'!$A:$AAQ, MATCH($A17, 'Weekly 스피킹'!$A:$A, 0), MATCH(TODAY() - WEEKDAY(TODAY(), 2) - 6, 'Weekly 스피킹'!$2:$2, 0)), ""), IF(val=0, "", val))} | R17: =LET(val, IF(OR(Q17="", P17=""), "", IFERROR((Q17 - P17) / ABS(P17), "")), IF(val=0, "", val)) | S17: =(S19 - S18) / S19 -> -0.012982011 | T17: =(T19 - T18) / T19 -> 0.50253884 | U17: =LET(val, IF(OR(T17="", S17=""), "", IFERROR((T17 - S17) / ABS(S17), "")), IF(val=0, "", val)) -> 39.710399
A18: Cost | B18: Cost | C18: ㄴ Cost | D18: {=LET(val, IFERROR(INDEX('Weekly 쨈 raw'!$A:$AAQ, MATCH(TODAY() - WEEKDAY(TODAY(), 2) - 13, 'Weekly 쨈 raw'!$A:$A, 0), MATCH($A18, 'Weekly 쨈 raw'!$1:$1, 0)), ""), IF(val=0, "", val))} -> 4067027.1 | E18: {=LET(val, IFERROR(INDEX('Weekly 쨈 raw'!$A:$AAQ, MATCH(TODAY() - WEEKDAY(TODAY(), 2) - 6, 'Weekly 쨈 raw'!$A:$A, 0), MATCH($A18, 'Weekly 쨈 raw'!$1:$1, 0)), ""), IF(val=0, "", val))} -> 5929382.6 | F18: =LET(val, IFERROR((E18 - D18) / D18, ""), IF(val=0, "", val)) -> 0.45791568 | G18: {=LET(val, IFERROR(INDEX('Monthly 쨈 M raw'!$A:$AAQ, MATCH(EOMONTH(TODAY(), -2) + 1, 'Monthly 쨈 M raw'!$A:$A, 0), MATCH($B18, 'Monthly 쨈 M raw'!$1:$1, 0)), ""), IF(val=0, "", val))} -> 9780318 | H18: {=LET(val, IFERROR(INDEX('Monthly 쨈 M raw'!$A:$AAQ, MATCH(EOMONTH(TODAY(), -1) + 1, 'Monthly 쨈 M raw'!$A:$A, 0), MATCH($B18, 'Monthly 쨈 M raw'!$1:$1, 0)), ""), IF(val=0, "", val))} -> 13448298 | I18: =LET(val, IF(OR(G18="", H18=""), "", IFERROR((H18 - G18) / G18, "")), IF(val=0, "", val)) -> 0.37503688 | J18: {=LET(val, IFERROR(INDEX('Weekly 사주 raw'!$A:$AAQ, MATCH(TODAY() - WEEKDAY(TODAY(), 2) - 13, 'Weekly 사주 raw'!$A:$A, 0), MATCH($A18, 'Weekly 사주 raw'!$1:$1, 0)), ""), IF(val=0, "", val))} -> 1166298.7 | K18: {=LET(val, IFERROR(INDEX('Weekly 사주 raw'!$A:$AAQ, MATCH(TODAY() - WEEKDAY(TODAY(), 2) - 6, 'Weekly 사주 raw'!$A:$A, 0), MATCH($A18, 'Weekly 사주 raw'!$1:$1, 0)), ""), IF(val=0, "", val))} -> 1426818.7 | L18: =LET(val, IFERROR((K18 - J18) / J18, ""), IF(val=0, "", val)) -> 0.22337337 | M18: {=LET(val, IFERROR(INDEX('Monthly 사주 M raw'!$A:$AAQ, MATCH(EOMONTH(TODAY(), -2) + 1, 'Monthly 사주 M raw'!$A:$A, 0), MATCH($B18, 'Monthly 사주 M raw'!$1:$1, 0)), ""), IF(val=0, "", val))} -> 5188048.5 | N18: {=LET(val, IFERROR(INDEX('Monthly 사주 M raw'!$A:$AAQ, MATCH(EOMONTH(TODAY(), -1) + 1, 'Monthly 사주 M raw'!$A:$A, 0), MATCH($B18, 'Monthly 사주 M raw'!$1:$1, 0)), ""), IF(val=0, "", val))} -> 4803597.3 | O18: =LET(val, IF(OR(M18="", N18=""), "", IFERROR((N18 - M18) / M18, "")), IF(val=0, "", val)) -> -0.074103247 | P18: {=LET(val, IFERROR(INDEX('Weekly 스피킹'!$A:$AAQ, MATCH($A18, 'Weekly 스피킹'!$A:$A, 0), MATCH(TODAY() - WEEKDAY(TODAY(), 2) - 13, 'Weekly 스피킹'!$2:$2, 0)), ""), IF(val=0, "", val))} -> 1169570 | Q18: {=LET(val, IFERROR(INDEX('Weekly 스피킹'!$A:$AAQ, MATCH($A18, 'Weekly 스피킹'!$A:$A, 0), MATCH(TODAY() - WEEKDAY(TODAY(), 2) - 6, 'Weekly 스피킹'!$2:$2, 0)), ""), IF(val=0, "", val))} | R18: =LET(val, IFERROR((Q18 - P18) / P18, ""), IF(val=0, "", val)) -> -1 | S18: {=SUM( INDEX('Daily 스피킹'!15:15, MATCH(EDATE(DATE(YEAR(TODAY()), MONTH(TODAY()), 1), -1), 'Daily 스피킹'!2:2, 0)) : INDEX('Daily 스피킹'!15:15, MATCH(EDATE(TODAY(), -1), 'Daily 스피킹'!2:2, 0)) )} -> 13974087 | T18: {=SUM( INDEX('Daily 스피킹'!15:15, MATCH(DATE(YEAR(TODAY()), MONTH(TODAY()), 1), 'Daily 스피킹'!2:2, 0)) : INDEX('Daily 스피킹'!15:15, MATCH(TODAY(), 'Daily 스피킹'!2:2, 0)) )} -> 4130420 | U18: =LET(val, IF(OR(S18="", T18=""), "", IFERROR((T18 - S18) / S18, "")), IF(val=0, "", val)) -> -0.7044229
A19: Revenue_ | B19: Revenue_ | C19: ㄴ Revenue | D19: {=LET(val, IFERROR(INDEX('Weekly 쨈 raw'!$A:$AAQ, MATCH(TODAY() - WEEKDAY(TODAY(), 2) - 13, 'Weekly 쨈 raw'!$A:$A, 0), MATCH($A19, 'Weekly 쨈 raw'!$1:$1, 0)), ""), IF(val=0, "", val))} -> 5923600 | E19: {=LET(val, IFERROR(INDEX('Weekly 쨈 raw'!$A:$AAQ, MATCH(TODAY() - WEEKDAY(TODAY(), 2) - 6, 'Weekly 쨈 raw'!$A:$A, 0), MATCH($A19, 'Weekly 쨈 raw'!$1:$1, 0)), ""), IF(val=0, "", val))} -> 8653000 | F19: =LET(val, IFERROR((E19 - D19) / D19, ""), IF(val=0, "", val)) -> 0.4607671 | G19: {=LET(val, IFERROR(INDEX('Monthly 쨈 M raw'!$A:$AAQ, MATCH(EOMONTH(TODAY(), -2) + 1, 'Monthly 쨈 M raw'!$A:$A, 0), MATCH($B19, 'Monthly 쨈 M raw'!$1:$1, 0)), 0), IF(val=0, "", val))} -> 11090200 | H19: {=LET(val, IFERROR(INDEX('Monthly 쨈 M raw'!$A:$AAQ, MATCH(EOMONTH(TODAY(), -1) + 1, 'Monthly 쨈 M raw'!$A:$A, 0), MATCH($B19, 'Monthly 쨈 M raw'!$1:$1, 0)), ""), IF(val=0, "", val))} -> 19118300 | I19: =LET(val, IF(OR(G19="", H19=""), "", IFERROR((H19 - G19) / G19, "")), IF(val=0, "", val)) -> 0.72389136 | J19: {=LET(val, IFERROR(INDEX('Weekly 사주 raw'!$A:$AAQ, MATCH(TODAY() - WEEKDAY(TODAY(), 2) - 13, 'Weekly 사주 raw'!$A:$A, 0), MATCH($A19, 'Weekly 사주 raw'!$1:$1, 0)), ""), IF(val=0, "", val))} -> 4444700 | K19: {=LET(val, IFERROR(INDEX('Weekly 사주 raw'!$A:$AAQ, MATCH(TODAY() - WEEKDAY(TODAY(), 2) - 6, 'Weekly 사주 raw'!$A:$A, 0), MATCH($A19, 'Weekly 사주 raw'!$1:$1, 0)), ""), IF(val=0, "", val))} -> 5224900 | L19: =LET(val, IFERROR((K19 - J19) / J19, ""), IF(val=0, "", val)) -> 0.17553491 | M19: {=LET(val, IFERROR(INDEX('Monthly 사주 M raw'!$A:$AAQ, MATCH(EOMONTH(TODAY(), -2) + 1, 'Monthly 사주 M raw'!$A:$A, 0), MATCH($B19, 'Monthly 사주 M raw'!$1:$1, 0)), ""), IF(val=0, "", val))} -> 20911600 | N19: {=LET(val, IFERROR(INDEX('Monthly 사주 M raw'!$A:$AAQ, MATCH(EOMONTH(TODAY(), -1) + 1, 'Monthly 사주 M raw'!$A:$A, 0), MATCH($B19, 'Monthly 사주 M raw'!$1:$1, 0)), ""), IF(val=0, "", val))} -> 17372800 | O19: =LET(val, IF(OR(M19="", N19=""), "", IFERROR((N19 - M19) / M19, "")), IF(val=0, "", val)) -> -0.16922665 | P19: {=LET(val, IFERROR(INDEX('Weekly 스피킹 raw'!$A:$AAQ, MATCH(TODAY() - WEEKDAY(TODAY(), 2) - 13, 'Weekly 스피킹 raw'!$A:$A, 0), MATCH($A19, 'Weekly 스피킹 raw'!$1:$1, 0)), ""), IF(val=0, "", val))} -> 1712000 | Q19: {=LET(val, IFERROR(INDEX('Weekly 스피킹 raw'!$A:$AAQ, MATCH(TODAY() - WEEKDAY(TODAY(), 2) - 6, 'Weekly 스피킹 raw'!$A:$A, 0), MATCH($A19, 'Weekly 스피킹 raw'!$1:$1, 0)), ""), IF(val=0, "", val))} -> 2212000 | R19: =LET(val, IFERROR((Q19 - P19) / P19, ""), IF(val=0, "", val)) -> 0.29205607 | S19: {=LET(val, IFERROR(INDEX('Monthly 스피킹 M raw'!$A:$AAQ, MATCH(EOMONTH(TODAY(), -2) + 1, 'Monthly 스피킹 M raw'!$A:$A, 0), MATCH($B19, 'Monthly 스피킹 M raw'!$1:$1, 0)), ""), IF(val=0, "", val))} -> 13795000 | T19: {=LET(val, IFERROR(INDEX('Monthly 스피킹 raw'!$A:$AAQ, MATCH(EOMONTH(TODAY(), -1) + 1, 'Monthly 스피킹 raw'!$A:$A, 0), MATCH($B19, 'Monthly 스피킹 raw'!$1:$1, 0)), ""), IF(val=0, "", val))} -> 8303000 | U19: =LET(val, IF(OR(S19="", T19=""), "", IFERROR((T19 - S19) / S19, "")), IF(val=0, "", val)) -> -0.39811526
C21: 퍼널 (신규) | D21: {=LET(val, IFERROR(INDEX('Weekly 쨈 raw'!$A:$AAQ, MATCH(TODAY() - WEEKDAY(TODAY(), 2) - 13, 'Weekly 쨈 raw'!$A:$A, 0), MATCH($A21, 'Weekly 쨈 raw'!$1:$1, 0)), ""), IF(val=0, "", val))} | E21: {=LET(val, IFERROR(INDEX('Weekly 쨈 raw'!$A:$AAQ, MATCH(TODAY() - WEEKDAY(TODAY(), 2) - 6, 'Weekly 쨈 raw'!$A:$A, 0), MATCH($A21, 'Weekly 쨈 raw'!$1:$1, 0)), ""), IF(val=0, "", val))} | F21: =LET(val, IFERROR((E21 - D21) / D21, ""), IF(val=0, "", val)) | G21: {=LET(val, IFERROR(INDEX('Monthly 쨈 M raw'!$A:$AAQ, MATCH(EOMONTH(TODAY(), -2) + 1, 'Monthly 쨈 M raw'!$A:$A, 0), MATCH($B21, 'Monthly 쨈 M raw'!$1:$1, 0)), 0), IF(val=0, "", val))} | H21: {=LET(val, IFERROR(INDEX('Monthly 쨈 M raw'!$A:$AAQ, MATCH(EOMONTH(TODAY(), -1) + 1, 'Monthly 쨈 M raw'!$A:$A, 0), MATCH($B21, 'Monthly 쨈 M raw'!$1:$1, 0)), ""), IF(val=0, "", val))} | I21: =LET(val, IF(OR(G21="", H21=""), "", IFERROR((H21 - G21) / G21, "")), IF(val=0, "", val)) | J21: {=LET(val, IFERROR(INDEX('Weekly 사주 raw'!$A:$AAQ, MATCH(TODAY() - WEEKDAY(TODAY(), 2) - 13, 'Weekly 사주 raw'!$A:$A, 0), MATCH($A21, 'Weekly 사주 raw'!$1:$1, 0)), ""), IF(val=0, "", val))} | K21: {=LET(val, IFERROR(INDEX('Weekly 사주 raw'!$A:$AAQ, MATCH(TODAY() - WEEKDAY(TODAY(), 2) - 6, 'Weekly 사주 raw'!$A:$A, 0), MATCH($A21, 'Weekly 사주 raw'!$1:$1, 0)), ""), IF(val=0, "", val))} | L21: =LET(val, IFERROR((K21 - J21) / J21, ""), IF(val=0, "", val)) | M21: {=LET(val, IFERROR(INDEX('Monthly 사주 raw'!$A:$AAQ, MATCH(EOMONTH(TODAY(), -2) + 1, 'Monthly 사주 raw'!$A:$A, 0), MATCH($B21, 'Monthly 사주 raw'!$1:$1, 0)), ""), IF(val=0, "", val))} | N21: {=LET(val, IFERROR(INDEX('Monthly 사주 M raw'!$A:$AAQ, MATCH(EOMONTH(TODAY(), -1) + 1, 'Monthly 사주 M raw'!$A:$A, 0), MATCH($B21, 'Monthly 사주 M raw'!$1:$1, 0)), ""), IF(val=0, "", val))} | O21: =LET(val, IF(OR(M21="", N21=""), "", IFERROR((N21 - M21) / M21, "")), IF(val=0, "", val)) | P21: {=LET(val, IFERROR(INDEX('Weekly 스피킹 raw'!$A:$AAQ, MATCH(TODAY() - WEEKDAY(TODAY(), 2) - 13, 'Weekly 스피킹 raw'!$A:$A, 0), MATCH($A21, 'Weekly 스피킹 raw'!$1:$1, 0)), ""), IF(val=0, "", val))} | Q21: {=LET(val, IFERROR(INDEX('Weekly 스피킹 raw'!$A:$AAQ, MATCH(TODAY() - WEEKDAY(TODAY(), 2) - 6, 'Weekly 스피킹 raw'!$A:$A, 0), MATCH($A21, 'Weekly 스피킹 raw'!$1:$1, 0)), ""), IF(val=0, "", val))} | R21: =LET(val, IFERROR((Q21 - P21) / P21, ""), IF(val=0, "", val)) | S21: {=LET(val, IFERROR(INDEX('Monthly 스피킹 M raw'!$A:$AAQ, MATCH(EOMONTH(TODAY(), -2) + 1, 'Monthly 스피킹 M raw'!$A:$A, 0), MATCH($B21, 'Monthly 스피킹 M raw'!$1:$1, 0)), ""), IF(val=0, "", val))} | T21: {=LET(val, IFERROR(INDEX('Monthly 스피킹 raw'!$A:$AAQ, MATCH(EOMONTH(TODAY(), -1) + 1, 'Monthly 스피킹 raw'!$A:$A, 0), MATCH($B21, 'Monthly 스피킹 raw'!$1:$1, 0)), ""), IF(val=0, "", val))} | U21: =LET(val, IF(OR(S21="", T21=""), "", IFERROR((T21 - S21) / S21, "")), IF(val=0, "", val))
A22: Install_User_New | B22: Install_User_New | C22: ㄴ Install User | D22: {=LET(val, IFERROR(INDEX('Weekly 쨈 raw'!$A:$AAQ, MATCH(TODAY() - WEEKDAY(TODAY(), 2) - 13, 'Weekly 쨈 raw'!$A:$A, 0), MATCH($A22, 'Weekly 쨈 raw'!$1:$1, 0)), ""), IF(val=0, "", val))} | E22: {=LET(val, IFERROR(INDEX('Weekly 쨈 raw'!$A:$AAQ, MATCH(TODAY() - WEEKDAY(TODAY(), 2) - 6, 'Weekly 쨈 raw'!$A:$A, 0), MATCH($A22, 'Weekly 쨈 raw'!$1:$1, 0)), ""), IF(val=0, "", val))} | F22: =LET(val, IFERROR((E22 - D22) / D22, ""), IF(val=0, "", val)) | G22: {=LET(val, IFERROR(INDEX('Monthly 쨈 M raw'!$A:$AAQ, MATCH(EOMONTH(TODAY(), -2) + 1, 'Monthly 쨈 M raw'!$A:$A, 0), MATCH($B22, 'Monthly 쨈 M raw'!$1:$1, 0)), 0), IF(val=0, "", val))} | H22: {=LET(val, IFERROR(INDEX('Monthly 쨈 M raw'!$A:$AAQ, MATCH(EOMONTH(TODAY(), -1) + 1, 'Monthly 쨈 M raw'!$A:$A, 0), MATCH($B22, 'Monthly 쨈 M raw'!$1:$1, 0)), ""), IF(val=0, "", val))} | I22: =LET(val, IF(OR(G22="", H22=""), "", IFERROR((H22 - G22) / G22, "")), IF(val=0, "", val)) | J22: {=LET(val, IFERROR(INDEX('Weekly 사주 raw'!$A:$AAQ, MATCH(TODAY() - WEEKDAY(TODAY(), 2) - 13, 'Weekly 사주 raw'!$A:$A, 0), MATCH($A22, 'Weekly 사주 raw'!$1:$1, 0)), ""), IF(val=0, "", val))} | K22: {=LET(val, IFERROR(INDEX('Weekly 사주 raw'!$A:$AAQ, MATCH(TODAY() - WEEKDAY(TODAY(), 2) - 6, 'Weekly 사주 raw'!$A:$A, 0), MATCH($A22, 'Weekly 사주 raw'!$1:$1, 0)), ""), IF(val=0, "", val))} | L22: =LET(val, IFERROR((K22 - J22) / J22, ""), IF(val=0, "", val)) | M22: {=LET(val, IFERROR(INDEX('Monthly 사주 raw'!$A:$AAQ, MATCH(EOMONTH(TODAY(), -2) + 1, 'Monthly 사주 raw'!$A:$A, 0), MATCH($B22, 'Monthly 사주 raw'!$1:$1, 0)), ""), IF(val=0, "", val))} | N22: {=LET(val, IFERROR(INDEX('Monthly 사주 M raw'!$A:$AAQ, MATCH(EOMONTH(TODAY(), -1) + 1, 'Monthly 사주 M raw'!$A:$A, 0), MATCH($B22, 'Monthly 사주 M raw'!$1:$1, 0)), ""), IF(val=0, "", val))} | O22: =LET(val, IF(OR(M22="", N22=""), "", IFERROR((N22 - M22) / M22, "")), IF(val=0, "", val)) | P22: {=LET(val, IFERROR(INDEX('Weekly 스피킹 raw'!$A:$AAQ, MATCH(TODAY() - WEEKDAY(TODAY(), 2) - 13, 'Weekly 스피킹 raw'!$A:$A, 0), MATCH($A22, 'Weekly 스피킹 raw'!$1:$1, 0)), ""), IF(val=0, "", val))} | Q22: {=LET(val, IFERROR(INDEX('Weekly 스피킹 raw'!$A:$AAQ, MATCH(TODAY() - WEEKDAY(TODAY(), 2) - 6, 'Weekly 스피킹 raw'!$A:$A, 0), MATCH($A22, 'Weekly 스피킹 raw'!$1:$1, 0)), ""), IF(val=0, "", val))} | R22: =LET(val, IFERROR((Q22 - P22) / P22, ""), IF(val=0, "", val)) | S22: {=LET(val, IFERROR(INDEX('Monthly 스피킹 M raw'!$A:$AAQ, MATCH(EOMONTH(TODAY(), -2) + 1, 'Monthly 스피킹 M raw'!$A:$A, 0), MATCH($B22, 'Monthly 스피킹 M raw'!$1:$1, 0)), ""), IF(val=0, "", val))} | T22: {=LET(val, IFERROR(INDEX('Monthly 스피킹 raw'!$A:$AAQ, MATCH(EOMONTH(TODAY(), -1) + 1, 'Monthly 스피킹 raw'!$A:$A, 0), MATCH($B22, 'Monthly 스피킹 raw'!$1:$1, 0)), ""), IF(val=0, "", val))} | U22: =LET(val, IF(OR(S22="", T22=""), "", IFERROR((T22 - S22) / S22, "")), IF(val=0, "", val))
A23: Sign_Up_User_New | B23: Sign_Up_User_New | C23: ㄴ Sign Up User | D23: {=LET(val, IFERROR(INDEX('Weekly 쨈 raw'!$A:$AAQ, MATCH(TODAY() - WEEKDAY(TODAY(), 2) - 13, 'Weekly 쨈 raw'!$A:$A, 0), MATCH($A23, 'Weekly 쨈 raw'!$1:$1, 0)), ""), IF(val=0, "", val))} | E23: {=LET(val, IFERROR(INDEX('Weekly 쨈 raw'!$A:$AAQ, MATCH(TODAY() - WEEKDAY(TODAY(), 2) - 6, 'Weekly 쨈 raw'!$A:$A, 0), MATCH($A23, 'Weekly 쨈 raw'!$1:$1, 0)), ""), IF(val=0, "", val))} | F23: =LET(val, IFERROR((E23 - D23) / D23, ""), IF(val=0, "", val)) | G23: {=LET(val, IFERROR(INDEX('Monthly 쨈 M raw'!$A:$AAQ, MATCH(EOMONTH(TODAY(), -2) + 1, 'Monthly 쨈 M raw'!$A:$A, 0), MATCH($B23, 'Monthly 쨈 M raw'!$1:$1, 0)), 0), IF(val=0, "", val))} | H23: {=LET(val, IFERROR(INDEX('Monthly 쨈 M raw'!$A:$AAQ, MATCH(EOMONTH(TODAY(), -1) + 1, 'Monthly 쨈 M raw'!$A:$A, 0), MATCH($B23, 'Monthly 쨈 M raw'!$1:$1, 0)), ""), IF(val=0, "", val))} | I23: =LET(val, IF(OR(G23="", H23=""), "", IFERROR((H23 - G23) / G23, "")), IF(val=0, "", val)) | J23: {=LET(val, IFERROR(INDEX('Weekly 사주 raw'!$A:$AAQ, MATCH(TODAY() - WEEKDAY(TODAY(), 2) - 13, 'Weekly 사주 raw'!$A:$A, 0), MATCH($A23, 'Weekly 사주 raw'!$1:$1, 0)), ""), IF(val=0, "", val))} | K23: {=LET(val, IFERROR(INDEX('Weekly 사주 raw'!$A:$AAQ, MATCH(TODAY() - WEEKDAY(TODAY(), 2) - 6, 'Weekly 사주 raw'!$A:$A, 0), MATCH($A23, 'Weekly 사주 raw'!$1:$1, 0)), ""), IF(val=0, "", val))} | L23: =LET(val, IFERROR((K23 - J23) / J23, ""), IF(val=0, "", val)) | M23: {=LET(val, IFERROR(INDEX('Monthly 사주 raw'!$A:$AAQ, MATCH(EOMONTH(TODAY(), -2) + 1, 'Monthly 사주 raw'!$A:$A, 0), MATCH($B23, 'Monthly 사주 raw'!$1:$1, 0)), ""), IF(val=0, "", val))} | N23: {=LET(val, IFERROR(INDEX('Monthly 사주 M raw'!$A:$AAQ, MATCH(EOMONTH(TODAY(), -1) + 1, 'Monthly 사주 M raw'!$A:$A, 0), MATCH($B23, 'Monthly 사주 M raw'!$1:$1, 0)), ""), IF(val=0, "", val))} | O23: =LET(val, IF(OR(M23="", N23=""), "", IFERROR((N23 - M23) / M23, "")), IF(val=0, "", val)) | P23: {=LET(val, IFERROR(INDEX('Weekly 스피킹 raw'!$A:$AAQ, MATCH(TODAY() - WEEKDAY(TODAY(), 2) - 13, 'Weekly 스피킹 raw'!$A:$A, 0), MATCH($A23, 'Weekly 스피킹 raw'!$1:$1, 0)), ""), IF(val=0, "", val))} | Q23: {=LET(val, IFERROR(INDEX('Weekly 스피킹 raw'!$A:$AAQ, MATCH(TODAY() - WEEKDAY(TODAY(), 2) - 6, 'Weekly 스피킹 raw'!$A:$A, 0), MATCH($A23, 'Weekly 스피킹 raw'!$1:$1, 0)), ""), IF(val=0, "", val))} | R23: =LET(val, IFERROR((Q23 - P23) / P23, ""), IF(val=0, "", val)) | S23: {=LET(val, IFERROR(INDEX('Monthly 스피킹 M raw'!$A:$AAQ, MATCH(EOMONTH(TODAY(), -2) + 1, 'Monthly 스피킹 M raw'!$A:$A, 0), MATCH($B23, 'Monthly 스피킹 M raw'!$1:$1, 0)), ""), IF(val=0, "", val))} | T23: {=LET(val, IFERROR(INDEX('Monthly 스피킹 raw'!$A:$AAQ, MATCH(EOMONTH(TODAY(), -1) + 1, 'Monthly 스피킹 raw'!$A:$A, 0), MATCH($B23, 'Monthly 스피킹 raw'!$1:$1, 0)), ""), IF(val=0, "", val))} | U23: =LET(val, IF(OR(S23="", T23=""), "", IFERROR((T23 - S23) / S23, "")), IF(val=0, "", val))
A24: Main_View_User_New | B24: Main_View_User_New | C24: ㄴ Main View User | D24: {=LET(val, IFERROR(INDEX('Weekly 쨈 raw'!$A:$AAQ, MATCH(TODAY() - WEEKDAY(TODAY(), 2) - 13, 'Weekly 쨈 raw'!$A:$A, 0), MATCH($A24, 'Weekly 쨈 raw'!$1:$1, 0)), ""), IF(val=0, "", val))} -> 4308 | E24: {=LET(val, IFERROR(INDEX('Weekly 쨈 raw'!$A:$AAQ, MATCH(TODAY() - WEEKDAY(TODAY(), 2) - 6, 'Weekly 쨈 raw'!$A:$A, 0), MATCH($A24, 'Weekly 쨈 raw'!$1:$1, 0)), ""), IF(val=0, "", val))} -> 4426 | F24: =LET(val, IFERROR((E24 - D24) / D24, ""), IF(val=0, "", val)) -> 0.027390901 | G24: {=LET(val, IFERROR(INDEX('Monthly 쨈 M raw'!$A:$AAQ, MATCH(EOMONTH(TODAY(), -2) + 1, 'Monthly 쨈 M raw'!$A:$A, 0), MATCH($B24, 'Monthly 쨈 M raw'!$1:$1, 0)), 0), IF(val=0, "", val))} -> 11015 | H24: {=LET(val, IFERROR(INDEX('Monthly 쨈 M raw'!$A:$AAQ, MATCH(EOMONTH(TODAY(), -1) + 1, 'Monthly 쨈 M raw'!$A:$A, 0), MATCH($B24, 'Monthly 쨈 M raw'!$1:$1, 0)), ""), IF(val=0, "", val))} -> 13278 | I24: =LET(val, IF(OR(G24="", H24=""), "", IFERROR((H24 - G24) / G24, "")), IF(val=0, "", val)) -> 0.20544712 | J24: {=LET(val, IFERROR(INDEX('Weekly 사주 raw'!$A:$AAQ, MATCH(TODAY() - WEEKDAY(TODAY(), 2) - 13, 'Weekly 사주 raw'!$A:$A, 0), MATCH($A24, 'Weekly 사주 raw'!$1:$1, 0)), ""), IF(val=0, "", val))} -> 3912 | K24: {=LET(val, IFERROR(INDEX('Weekly 사주 raw'!$A:$AAQ, MATCH(TODAY() - WEEKDAY(TODAY(), 2) - 6, 'Weekly 사주 raw'!$A:$A, 0), MATCH($A24, 'Weekly 사주 raw'!$1:$1, 0)), ""), IF(val=0, "", val))} -> 1845 | L24: =LET(val, IFERROR((K24 - J24) / J24, ""), IF(val=0, "", val)) -> -0.52837423 | M24: {=LET(val, IFERROR(INDEX('Monthly 사주 M raw'!$A:$AAQ, MATCH(EOMONTH(TODAY(), -2) + 1, 'Monthly 사주 M raw'!$A:$A, 0), MATCH($B24, 'Monthly 사주 M raw'!$1:$1, 0)), ""), IF(val=0, "", val))} -> 14126 | N24: {=LET(val, IFERROR(INDEX('Monthly 사주 M raw'!$A:$AAQ, MATCH(EOMONTH(TODAY(), -1) + 1, 'Monthly 사주 M raw'!$A:$A, 0), MATCH($B24, 'Monthly 사주 M raw'!$1:$1, 0)), ""), IF(val=0, "", val))} -> 13219 | O24: =LET(val, IF(OR(M24="", N24=""), "", IFERROR((N24 - M24) / M24, "")), IF(val=0, "", val)) -> -0.064207844 | P24: {=LET(val, IFERROR(INDEX('Weekly 스피킹 raw'!$A:$AAQ, MATCH(TODAY() - WEEKDAY(TODAY(), 2) - 13, 'Weekly 스피킹 raw'!$A:$A, 0), MATCH($A24, 'Weekly 스피킹 raw'!$1:$1, 0)), ""), IF(val=0, "", val))} -> 3452 | Q24: {=LET(val, IFERROR(INDEX('Weekly 스피킹 raw'!$A:$AAQ, MATCH(TODAY() - WEEKDAY(TODAY(), 2) - 6, 'Weekly 스피킹 raw'!$A:$A, 0), MATCH($A24, 'Weekly 스피킹 raw'!$1:$1, 0)), ""), IF(val=0, "", val))} -> 1453 | R24: =LET(val, IFERROR((Q24 - P24) / P24, ""), IF(val=0, "", val)) -> -0.57908459 | S24: {=LET(val, IFERROR(INDEX('Monthly 스피킹 M raw'!$A:$AAQ, MATCH(EOMONTH(TODAY(), -2) + 1, 'Monthly 스피킹 M raw'!$A:$A, 0), MATCH($B24, 'Monthly 스피킹 M raw'!$1:$1, 0)), ""), IF(val=0, "", val))} -> 10369 | T24: {=LET(val, IFERROR(INDEX('Monthly 스피킹 raw'!$A:$AAQ, MATCH(EOMONTH(TODAY(), -1) + 1, 'Monthly 스피킹 raw'!$A:$A, 0), MATCH($B24, 'Monthly 스피킹 raw'!$1:$1, 0)), ""), IF(val=0, "", val))} -> 10502 | U24: =LET(val, IF(OR(S24="", T24=""), "", IFERROR((T24 - S24) / S24, "")), IF(val=0, "", val)) -> 0.012826695
A25: Product_View_User_New | B25: Product_View_User_New | C25: ㄴ Product View User | D25: {=LET(val, IFERROR(INDEX('Weekly 쨈 raw'!$A:$AAQ, MATCH(TODAY() - WEEKDAY(TODAY(), 2) - 13, 'Weekly 쨈 raw'!$A:$A, 0), MATCH($A25, 'Weekly 쨈 raw'!$1:$1, 0)), ""), IF(val=0, "", val))} -> 2886 | E25: {=LET(val, IFERROR(INDEX('Weekly 쨈 raw'!$A:$AAQ, MATCH(TODAY() - WEEKDAY(TODAY(), 2) - 6, 'Weekly 쨈 raw'!$A:$A, 0), MATCH($A25, 'Weekly 쨈 raw'!$1:$1, 0)), ""), IF(val=0, "", val))} -> 3496 | F25: =LET(val, IFERROR((E25 - D25) / D25, ""), IF(val=0, "", val)) -> 0.21136521 | G25: {=LET(val, IFERROR(INDEX('Monthly 쨈 M raw'!$A:$AAQ, MATCH(EOMONTH(TODAY(), -2) + 1, 'Monthly 쨈 M raw'!$A:$A, 0), MATCH($B25, 'Monthly 쨈 M raw'!$1:$1, 0)), 0), IF(val=0, "", val))} -> 3611 | H25: {=LET(val, IFERROR(INDEX('Monthly 쨈 M raw'!$A:$AAQ, MATCH(EOMONTH(TODAY(), -1) + 1, 'Monthly 쨈 M raw'!$A:$A, 0), MATCH($B25, 'Monthly 쨈 M raw'!$1:$1, 0)), ""), IF(val=0, "", val))} -> 8504 | I25: =LET(val, IF(OR(G25="", H25=""), "", IFERROR((H25 - G25) / G25, "")), IF(val=0, "", val)) -> 1.3550263 | J25: {=LET(val, IFERROR(INDEX('Weekly 사주 raw'!$A:$AAQ, MATCH(TODAY() - WEEKDAY(TODAY(), 2) - 13, 'Weekly 사주 raw'!$A:$A, 0), MATCH($A25, 'Weekly 사주 raw'!$1:$1, 0)), ""), IF(val=0, "", val))} -> 1249 | K25: {=LET(val, IFERROR(INDEX('Weekly 사주 raw'!$A:$AAQ, MATCH(TODAY() - WEEKDAY(TODAY(), 2) - 6, 'Weekly 사주 raw'!$A:$A, 0), MATCH($A25, 'Weekly 사주 raw'!$1:$1, 0)), ""), IF(val=0, "", val))} -> 870 | L25: =LET(val, IFERROR((K25 - J25) / J25, ""), IF(val=0, "", val)) -> -0.30344275 | M25: {=LET(val, IFERROR(INDEX('Monthly 사주 M raw'!$A:$AAQ, MATCH(EOMONTH(TODAY(), -2) + 1, 'Monthly 사주 M raw'!$A:$A, 0), MATCH($B25, 'Monthly 사주 M raw'!$1:$1, 0)), ""), IF(val=0, "", val))} -> 7312 | N25: {=LET(val, IFERROR(INDEX('Monthly 사주 M raw'!$A:$AAQ, MATCH(EOMONTH(TODAY(), -1) + 1, 'Monthly 사주 M raw'!$A:$A, 0), MATCH($B25, 'Monthly 사주 M raw'!$1:$1, 0)), ""), IF(val=0, "", val))} -> 4487 | O25: =LET(val, IF(OR(M25="", N25=""), "", IFERROR((N25 - M25) / M25, "")), IF(val=0, "", val)) -> -0.3863512 | P25: {=LET(val, IFERROR(INDEX('Weekly 스피킹 raw'!$A:$AAQ, MATCH(TODAY() - WEEKDAY(TODAY(), 2) - 13, 'Weekly 스피킹 raw'!$A:$A, 0), MATCH($A25, 'Weekly 스피킹 raw'!$1:$1, 0)), ""), IF(val=0, "", val))} -> 925 | Q25: {=LET(val, IFERROR(INDEX('Weekly 스피킹 raw'!$A:$AAQ, MATCH(TODAY() - WEEKDAY(TODAY(), 2) - 6, 'Weekly 스피킹 raw'!$A:$A, 0), MATCH($A25, 'Weekly 스피킹 raw'!$1:$1, 0)), ""), IF(val=0, "", val))} -> 498 | R25: =LET(val, IFERROR((Q25 - P25) / P25, ""), IF(val=0, "", val)) -> -0.46162162 | S25: {=LET(val, IFERROR(INDEX('Monthly 스피킹 M raw'!$A:$AAQ, MATCH(EOMONTH(TODAY(), -2) + 1, 'Monthly 스피킹 M raw'!$A:$A, 0), MATCH($B25, 'Monthly 스피킹 M raw'!$1:$1, 0)), ""), IF(val=0, "", val))} -> 3789 | T25: {=LET(val, IFERROR(INDEX('Monthly 스피킹 raw'!$A:$AAQ, MATCH(EOMONTH(TODAY(), -1) + 1, 'Monthly 스피킹 raw'!$A:$A, 0), MATCH($B25, 'Monthly 스피킹 raw'!$1:$1, 0)), ""), IF(val=0, "", val))} -> 2975 | U25: =LET(val, IF(OR(S25="", T25=""), "", IFERROR((T25 - S25) / S25, "")), IF(val=0, "", val)) -> -0.21483241
